<?xml version="1.0" encoding="utf-8"?>
<!-- This URDF was automatically created by SolidWorks to URDF Exporter! Originally created by Stephen Brawner (brawner@gmail.com) 
     Commit Version: 1.6.0-1-g15f4949  Build Version: 1.6.7594.29634
     For more information, please see http://wiki.ros.org/sw_urdf_exporter -->
<robot
  name="finalassemblya">
  <link
    name="base_link">
    <inertial>
      <origin
        xyz="-0.0163088049904633 0.00261010883641098 0.0762443527255097"
        rpy="0 0 0" />
      <mass
        value="4.09200979800817" />
      <inertia
        ixx="0.0376183769050628"
        ixy="-5.70247759833753E-05"
        ixz="-0.0015059015433038"
        iyy="0.0375623611723881"
        iyz="7.83750367463489E-05"
        izz="0.0301842792756295" />
    </inertial>
    <visual>
      <origin
        xyz="0 0 0"
        rpy="0 0 0" />
      <geometry>
        <mesh
          filename="package://multi_robot/meshes/base_link.STL" />
      </geometry>
      <material
        name="">
        <color
          rgba="0.792156862745098 0.819607843137255 0.933333333333333 1" />
      </material>
    </visual>
    <collision>
      <origin
        xyz="0 0 0"
        rpy="0 0 0" />
      <geometry>
        <mesh
          filename="package://multi_robot/meshes/base_link.STL" />
      </geometry>
    </collision>
  </link>
  <link
    name="frontleftlink">
    <inertial>
      <origin
        xyz="-2.9143E-15 -0.015279 1.027E-15"
        rpy="0 0 0" />
      <mass
        value="0.40269" />
      <inertia
        ixx="0.00046246"
        ixy="2.0438E-20"
        ixz="-8.5382E-18"
        iyy="0.00082874"
        iyz="-1.2843E-20"
        izz="0.00046246" />
    </inertial>
    <visual>
      <origin
        xyz="0 0 0"
        rpy="0 0 0" />
      <geometry>
        <mesh
          filename="package://multi_robot/meshes/frontleftlink.STL" />
      </geometry>
      <material
        name="">
        <color
          rgba="0.79216 0.81961 0.93333 1" />
      </material>
    </visual>
    <collision>
      <origin
        xyz="0 0 0"
        rpy="0 0 0" />
      <geometry>
        <mesh
          filename="package://multi_robot/meshes/frontleftlink.STL" />
      </geometry>
    </collision>
  </link>
  <joint
    name="frontleftjoint"
    type="continuous">
    <origin
      xyz="0.063212 0.15653 -0.04"
      rpy="0 0 0" />
    <parent
      link="base_link" />
    <child
      link="frontleftlink" />
    <axis
      xyz="0 1 0" />
    <limit
      effort="1"
      velocity="1" />
  </joint>
  <link
    name="backleftlink">
    <inertial>
      <origin
        xyz="-2.9421E-15 -0.015279 1.0408E-15"
        rpy="0 0 0" />
      <mass
        value="0.40269" />
      <inertia
        ixx="0.00046246"
        ixy="-1.6824E-20"
        ixz="-8.3075E-18"
        iyy="0.00082874"
        iyz="-6.7316E-20"
        izz="0.00046246" />
    </inertial>
    <visual>
      <origin
        xyz="0 0 0"
        rpy="0 0 0" />
      <geometry>
        <mesh
          filename="package://multi_robot/meshes/backleftlink.STL" />
      </geometry>
      <material
        name="">
        <color
          rgba="0.79216 0.81961 0.93333 1" />
      </material>
    </visual>
    <collision>
      <origin
        xyz="0 0 0"
        rpy="0 0 0" />
      <geometry>
        <mesh
          filename="package://multi_robot/meshes/backleftlink.STL" />
      </geometry>
    </collision>
  </link>
  <joint
    name="backleftjoint"
    type="continuous">
    <origin
      xyz="-0.10279 0.15653 -0.04"
      rpy="0 0 0" />
    <parent
      link="base_link" />
    <child
      link="backleftlink" />
    <axis
      xyz="0 1 0" />
    <limit
      effort="1"
      velocity="1" />
  </joint>
  <link
    name="backrightlink">
    <inertial>
      <origin
        xyz="2.1094E-15 0.015279 -2.3176E-15"
        rpy="0 0 0" />
      <mass
        value="0.40269" />
      <inertia
        ixx="0.00046246"
        ixy="1.3769E-22"
        ixz="8.9074E-19"
        iyy="0.00082874"
        iyz="-1.1533E-19"
        izz="0.00046246" />
    </inertial>
    <visual>
      <origin
        xyz="0 0 0"
        rpy="0 0 0" />
      <geometry>
        <mesh
          filename="package://multi_robot/meshes/backrightlink.STL" />
      </geometry>
      <material
        name="">
        <color
          rgba="0.79216 0.81961 0.93333 1" />
      </material>
    </visual>
    <collision>
      <origin
        xyz="0 0 0"
        rpy="0 0 0" />
      <geometry>
        <mesh
          filename="package://multi_robot/meshes/backrightlink.STL" />
      </geometry>
    </collision>
  </link>
  <joint
    name="backrightjoint"
    type="continuous">
    <origin
      xyz="-0.10279 -0.15347 -0.04"
      rpy="0 0 0" />
    <parent
      link="base_link" />
    <child
      link="backrightlink" />
    <axis
      xyz="0 -1 0" />
    <limit
      effort="1"
      velocity="1" />
  </joint>
  <link
    name="frontrightlink">
    <inertial>
      <origin
        xyz="2.1094E-15 0.015279 -2.3176E-15"
        rpy="0 0 0" />
      <mass
        value="0.40269" />
      <inertia
        ixx="0.00046246"
        ixy="2.1404E-20"
        ixz="8.9934E-19"
        iyy="0.00082874"
        iyz="-6.7806E-20"
        izz="0.00046246" />
    </inertial>
    <visual>
      <origin
        xyz="0 0 0"
        rpy="0 0 0" />
      <geometry>
        <mesh
          filename="package://multi_robot/meshes/frontrightlink.STL" />
      </geometry>
      <material
        name="">
        <color
          rgba="0.79216 0.81961 0.93333 1" />
      </material>
    </visual>
    <collision>
      <origin
        xyz="0 0 0"
        rpy="0 0 0" />
      <geometry>
        <mesh
          filename="package://multi_robot/meshes/frontrightlink.STL" />
      </geometry>
    </collision>
  </link>
  <joint
    name="frontrightjoint"
    type="continuous">
    <origin
      xyz="0.063212 -0.15347 -0.04"
      rpy="0 0 0" />
    <parent
      link="base_link" />
    <child
      link="frontrightlink" />
    <axis
      xyz="0 -1 0" />
    <limit
      effort="1"
      velocity="1" />
  </joint>
  <link
    name="moplink">
    <inertial>
      <origin
        xyz="0 0 0.021249"
        rpy="0 0 0" />
      <mass
        value="0.40361" />
      <inertia
        ixx="0.0003662"
        ixy="4.0749E-20"
        ixz="-9.6371E-21"
        iyy="0.0003662"
        iyz="-9.6607E-21"
        izz="0.00061088" />
    </inertial>
    <visual>
      <origin
        xyz="0 0 0"
        rpy="0 0 0" />
      <geometry>
        <mesh
          filename="package://multi_robot/meshes/moplink.STL" />
      </geometry>
      <material
        name="">
        <color
          rgba="0.79216 0.81961 0.93333 1" />
      </material>
    </visual>
    <collision>
      <origin
        xyz="0 0 0"
        rpy="0 0 0" />
      <geometry>
        <mesh
          filename="package://multi_robot/meshes/moplink.STL" />
      </geometry>
    </collision>
  </link>
  <joint
    name="mopjoint"
    type="continuous">
    <origin
      xyz="-0.079788 0.0015322 -0.075"
      rpy="0 0 0" />
    <parent
      link="base_link" />
    <child
      link="moplink" />
    <axis
      xyz="0 0 -1" />
    <limit
      effort="0"
      velocity="10" />
  </joint>
    <gazebo>
    <plugin name="object_controller" filename="libgazebo_ros_planar_move.so">
      <commandTopic>cmd_vel</commandTopic>
      <odometryTopic>odom</odometryTopic>
      <odometryFrame>odom</odometryFrame>
      <odometryRate>20.0</odometryRate>
      <robotBaseFrame>base_link</robotBaseFrame>
    </plugin>
  </gazebo>
</robot>
